Workbook

Sheet PRUEBA_HISTÓRICO
B3: AÑO | C3: TRIMESTRE | D3: MES | E3: DIA | F3: DEMANDA | H3: DEMANDA PERDIDA | I3: ALMACEN | J3: CAMION | K3: EN PROCESO | M3: CAPACIDAD | N3: ROP | Q3: INICIO
B4: - | C4: - | D4: - | E4: 0 | F4: - | H4: - | I4: 0 | K4: 150 | M4: 20 | N4: 150
B5: 2025 | C5: I | D5: Enero | E5: 1 | F5: 12 | H5: 12 | I5: 0 | K5: 150 | M5: 20 | N5: 150 | Q5: Ingresos
E6: 2 | F6: 40 | H6: 40 | I6: 0 | K6: 150 | M6: 20 | N6: 150 | Q6: Precio por bidón | R6: 1450 | S6: Ingreso por unidad vendida
E7: 3 | F7: 45 | H7: 45 | I7: 0 | K7: 150 | M7: 20 | N7: 150 | Q7: Costos de Pedido
E8: 4 | F8: 34 | H8: 34 | I8: 0 | K8: 150 | M8: 20 | N8: 150 | Q8: Costo por pedido (S) | R8: 1500 | S8: Costo fijo por cada lote de producción activado
E9: 5 | F9: 37 | H9: 37 | I9: 0 | K9: 150 | M9: 20 | N9: 150 | Q9: Costo unitario producción | R9: 1000 | S9: Costo variable por cada bidón producido
E10: 6 | F10: 45 | H10: 45 | I10: 0 | K10: 150 | M10: 20 | N10: 150 | Q10: Costos de Inventario
E11: 7 | F11: 38 | H11: 38 | I11: 0 | J11: 150 | K11: 150 | M11: ="10 - 10" -> 10 - 10 | N11: 150 | Q11: Costo inventario anual (H) | R11: 100 | S11: Costo de mantener un bidón en almacén por un año
E12: 8 | F12: 32 | H12: 32 | I12: 0 | J12: 150 | K12: 150 | M12: 20 | N12: 150 | Q12: Costos de Envío
E13: 9 | F13: 33 | H13: 33 | I13: 0 | J13: 150 | K13: 150 | M13: 20 | N13: 150 | Q13: Costo envío por camión | R13: 15000 | S13: Costo fijo para envíos de hasta 200 bidones
E14: 10 | F14: 40 | H14: 40 | I14: 0 | J14: 150 | K14: 150 | M14: 20 | N14: 150 | Q14: Costo envío por correo | R14: 150 | S14: Costo por bidón para envíos individuales
E15: 11 | F15: 36 | H15: 36 | I15: 0 | J15: 150 | K15: 150 | M15: 20 | N15: 150 | Q15: Tiempos de Entrega
E16: 12 | F16: 44 | H16: 44 | I16: 0 | J16: 150 | K16: 150 | M16: 20 | N16: 150 | Q16: Lead Time camión (LTc) | R16: 7 | S16: Días que tarda en llegar un pedido por camión
E17: 13 | F17: 35 | H17: 35 | I17: 0 | J17: 150 | K17: 150 | M17: 20 | N17: 150 | Q17: Lead Time correo (LTm) | R17: 1 | S17: Días que tarda en llegar un pedido por correo
E18: 14 | F18: 44 | H18: 27 | I18: 150 | K18: 150 | M18: 20 | N18: 150 | Q18: Operaciones
E19: 15 | F19: 48 | H19: 0 | I19: =I18-F19-F18 -> 58 | J19: 150 | K19: 150 | M19: 20 | N19: 150 | Q19: Capacidad actual fábrica | R19: 20 | S19: Máximo de bidones que se pueden producir por día
E20: 16 | F20: 51 | H20: 0 | I20: =I19-F20 -> 7 | J20: 150 | K20: 150 | M20: 20 | N20: 150 | Q20: Financieros
E21: 17 | F21: 37 | H21: 3 | I21: 0 | J21: 150 | K21: 150 | M21: 20 | N21: 150 | Q21: Interés efectivo diario | R21: 0.0002739726 | S21: Tasa de interés diaria que genera el efectivo disponible
E22: 18 | F22: 34 | H22: 34 | I22: 0 | J22: 150 | K22: 150 | M22: 20 | N22: 150
E23: 19 | F23: 44 | H23: 44 | I23: 0 | J23: 150 | K23: 150 | M23: 20 | N23: 150
E24: 20 | F24: 32 | H24: 32 | I24: 0 | J24: 150 | K24: 150 | M24: 20 | N24: 150
E25: 21 | F25: 45 | H25: 45 | I25: 0 | J25: 150 | K25: 150 | M25: 20 | N25: 150
E26: 22 | F26: 53 | H26: 0 | I26: 150 | K26: 150 | M26: ="10 - 10" -> 10 - 10 | N26: 150
E27: 23 | F27: 48 | H27: 0 | I27: =I26-F27-F26 -> 49 | J27: 150 | K27: 150 | M27: 20 | N27: 150
E28: 24 | F28: 28 | H28: 0 | I28: =I27-F28 -> 21 | J28: 150 | K28: 150 | M28: 20 | N28: 150
E29: 25 | F29: 45 | H29: 24 | I29: 0 | J29: 150 | K29: 150 | M29: 20 | N29: 150
E30: 26 | F30: 36 | H30: 36 | I30: 0 | J30: 150 | K30: 150 | M30: 20 | N30: 150
E31: 27 | F31: 32 | H31: 32 | I31: 0 | J31: 150 | K31: 150 | M31: 20 | N31: 150
E32: 28 | F32: 50 | H32: 50 | I32: 0 | J32: 150 | K32: 150 | M32: 20 | N32: 150
E33: 29 | F33: 26 | H33: 11 | I33: 0 | J33: 150 | K33: 150 | M33: 20 | N33: 150
E34: 30 | F34: 43 | H34: 0 | I34: 150 | K34: 150 | M34: 20 | N34: 150
E35: 31 | F35: 54 | H35: 0 | I35: =I34-F35-F34 -> 53 | J35: 150 | K35: 150 | M35: 20 | N35: 150
D36: Febrero | E36: 32 | F36: 45 | H36: 7 | I36: =I35-F36 -> 8 | J36: 150 | K36: 150 | M36: 20 | N36: 150
E37: 33 | F37: 39 | H37: 39 | I37: 0 | J37: 150 | K37: 150 | M37: 20 | N37: 150
E38: 34 | F38: 39 | H38: 39 | I38: 0 | J38: 150 | K38: 150 | M38: 20 | N38: 150
E39: 35 | F39: 51 | H39: 51 | I39: 0 | J39: 150 | K39: 150 | M39: 20 | N39: 150
E40: 36 | F40: 49 | H40: 49 | I40: 0 | J40: 150 | K40: 150 | M40: 20 | N40: 150
E41: 37 | F41: 35 | H41: 0 | I41: 0 | J41: 150 | K41: 150 | M41: ="10 - 10" -> 10 - 10 | N41: 150
E42: 38 | F42: 45 | H42: 0 | I42: 150 | K42: 150 | M42: 20 | N42: 150
...

Sheet PROYECCIÓN_PREVISIÓN_EDITAR
B1: AÑO | C1: TRIMESTRE | D1: MES | E1: DIA | F1: DEMANDA | H1: ALMACEN | I1: CAMION | J1: EN PROCESO | L1: CAPACIDAD | M1: ROP | Y1: HORA | Z1: DÍA
B2: - | C2: - | D2: - | E2: 730 | F2: =PRUEBA_HISTÓRICO!F734 -> 24 | H2: 0 | I2: 150 | J2: 150 | L2: 20 | M2: 1200 | Y2: 10.916667 | Z2: 0
B3: 2027 | C3: I | D3: Enero | E3: 731 | F3: =DEMANDA_PREVISIÓN!E735 -> 44 | H3: 0 | I3: 150 | J3: 150 | L3: 20 | M3: 1200 | Y3: 10.926273
E4: 732 | F4: =DEMANDA_PREVISIÓN!E736 -> 41 | H4: 0 | I4: 150 | J4: 150 | L4: 20 | M4: 1200 | Y4: 10.93588
E5: 733 | F5: =DEMANDA_PREVISIÓN!E737 -> 41 | H5: 0 | I5: 150 | J5: 150 | L5: 20 | M5: 1200 | Y5: 10.945486
E6: 734 | F6: =DEMANDA_PREVISIÓN!E738 -> 54 | H6: 150 | J6: 150 | L6: 20 | M6: 1200 | Y6: 10.955093
E7: 735 | F7: =DEMANDA_PREVISIÓN!E739 -> 40 | H7: =H6-F7 -> 110 | I7: 150 | J7: 150 | L7: 20 | M7: 1200 | Y7: 10.964699
E8: 736 | F8: =DEMANDA_PREVISIÓN!E740 -> 46 | H8: =H7-F8 -> 64 | I8: 150 | J8: 200 | L8: 20 | M8: 1200 | Y8: 10.974306
E9: 737 | F9: =DEMANDA_PREVISIÓN!E741 -> 33 | H9: =H8-F9 -> 31 | I9: 150 | J9: 200 | L9: 20 | M9: 1200 | Y9: 10.983912
E10: 738 | F10: =DEMANDA_PREVISIÓN!E742 -> 46 | H10: 0 | I10: 150 | J10: 200 | L10: 20 | M10: 1200 | Y10: 10.993519
E11: 739 | F11: =DEMANDA_PREVISIÓN!E743 -> 37 | H11: 0 | I11: 150 | J11: 200 | L11: 20 | M11: 1200 | Y11: 11.003125 | Z11: 1
E12: 740 | F12: =DEMANDA_PREVISIÓN!E744 -> 35 | H12: 0 | I12: 150 | J12: 200 | L12: 20 | M12: 1200 | Y12: 11.012731
E13: 741 | F13: =DEMANDA_PREVISIÓN!E745 -> 37 | H13: 0 | I13: 150 | J13: 200 | L13: 20 | M13: 1200 | Y13: 11.022338
E14: 742 | F14: =DEMANDA_PREVISIÓN!E746 -> 31 | H14: 150 | J14: 200 | L14: 20 | M14: 1200 | Y14: 11.031944
E15: 743 | F15: =DEMANDA_PREVISIÓN!E747 -> 46 | H15: =H14-F15 -> 104 | J15: 200 | L15: 20 | M15: 1200 | Y15: 11.041551
E16: 744 | F16: =DEMANDA_PREVISIÓN!E748 -> 47 | H16: =H15-F16 -> 57 | J16: 200 | L16: 20 | M16: 1200 | Y16: 11.051157
E17: 745 | F17: =DEMANDA_PREVISIÓN!E749 -> 34 | H17: =H16-F17 -> 23 | I17: 200 | J17: 200 | L17: 20 | M17: 1200 | Y17: 11.060764
E18: 746 | F18: =DEMANDA_PREVISIÓN!E750 -> 41 | H18: 0 | I18: 200 | J18: 200 | L18: 200 | M18: 1200 | Y18: 11.07037
E19: 747 | F19: =DEMANDA_PREVISIÓN!E751 -> 40 | H19: 0 | I19: 200 | J19: 200 | L19: 200 | M19: 1200 | Y19: 11.079977
E20: 748 | F20: =DEMANDA_PREVISIÓN!E752 -> 28 | H20: 0 | I20: 200 | J20: 200 | L20: 200 | M20: 1200 | Y20: 11.089583
E21: 749 | F21: =DEMANDA_PREVISIÓN!E753 -> 42 | H21: 0 | I21: 200 | J21: 200 | L21: 200 | M21: 1200 | Y21: 11.09919
E22: 750 | F22: =DEMANDA_PREVISIÓN!E754 -> 32 | H22: 0 | I22: 200 | J22: 200 | L22: 200 | M22: 1200 | Y22: 11.108796
E23: 751 | F23: =DEMANDA_PREVISIÓN!E755 -> 48 | H23: 0 | I23: 200 | J23: 200 | L23: 200 | M23: 1200 | Y23: 11.118403
E24: 752 | F24: =DEMANDA_PREVISIÓN!E756 -> 31 | H24: 200 | J24: 200 | L24: 200 | M24: 1200 | Y24: 11.128009
E25: 753 | F25: =DEMANDA_PREVISIÓN!E757 -> 48 | H25: =H24-F25 -> 152 | J25: 200 | L25: 200 | M25: 1200 | Y25: 11.137616
E26: 754 | F26: =DEMANDA_PREVISIÓN!E758 -> 50 | H26: =H25-F26 -> 102 | J26: 200 | L26: 200 | M26: 1200 | Y26: 11.147222
E27: 755 | F27: =DEMANDA_PREVISIÓN!E759 -> 38 | H27: =H26-F27 -> 64 | I27: 200 | J27: 200 | L27: 200 | M27: 1200 | Y27: 11.156829
E28: 756 | F28: =DEMANDA_PREVISIÓN!E760 -> 31 | H28: =H27-F28 -> 33 | I28: 200 | J28: 200 | L28: 20 | M28: 1200 | Y28: 11.166435
E29: 757 | F29: =DEMANDA_PREVISIÓN!E761 -> 41 | H29: 0 | I29: 200 | J29: 200 | L29: 20 | M29: 1200 | Y29: 11.176042
E30: 758 | F30: =DEMANDA_PREVISIÓN!E762 -> 44 | H30: 0 | I30: 200 | J30: 200 | L30: 20 | M30: 1200 | Y30: 11.185648
E31: 759 | F31: =DEMANDA_PREVISIÓN!E763 -> 34 | H31: 0 | I31: 200 | J31: 200 | L31: 20 | M31: 1200 | Y31: 11.195255
E32: 760 | F32: =DEMANDA_PREVISIÓN!E764 -> 34 | H32: 0 | I32: 200 | J32: 200 | L32: 20 | M32: 1200 | Y32: 11.204861
E33: 761 | F33: =DEMANDA_PREVISIÓN!E765 -> 49 | H33: 0 | I33: 200 | J33: 200 | L33: 20 | M33: 1200 | Y33: 11.214468
D34: Febrero | E34: 762 | F34: =DEMANDA_PREVISIÓN!E766 -> 41 | H34: 200 | J34: 200 | L34: 20 | M34: 1200 | Y34: 11.224074
E35: 763 | F35: =DEMANDA_PREVISIÓN!E767 -> 40 | H35: =H34-F35 -> 160 | J35: 200 | L35: 20 | M35: 1200 | Y35: 11.233681
E36: 764 | F36: =DEMANDA_PREVISIÓN!E768 -> 46 | H36: =H35-F36 -> 114 | J36: 200 | L36: 20 | M36: 1200 | Y36: 11.243287
E37: 765 | F37: =DEMANDA_PREVISIÓN!E769 -> 31 | H37: =H36-F37 -> 83 | I37: 200 | J37: 200 | L37: 20 | M37: 1200 | Y37: 11.252894
E38: 766 | F38: =DEMANDA_PREVISIÓN!E770 -> 38 | H38: =H37-F38 -> 45 | I38: 200 | J38: 200 | L38: 20 | M38: 1200 | Y38: 11.2625
E39: 767 | F39: =DEMANDA_PREVISIÓN!E771 -> 39 | H39: =H38-F39 -> 6 | I39: 200 | J39: 200 | L39: 20 | M39: 1200 | Y39: 11.272106
E40: 768 | F40: =DEMANDA_PREVISIÓN!E772 -> 40 | H40: 0 | I40: 200 | J40: 200 | L40: 20 | M40: 1200 | Y40: 11.281713
...

Sheet DEMANDA_PREVISIÓN
B2: DEMANDA | H2: GRÁFICO DE LA DEMANDA
B4: DÍA | C4: FECHA | D4: HISTÓRICO | E4: PREVISIÓN
B5: 1 | C5: 45658 | D5: 12
B6: 2 | C6: 45659 | D6: 40
B7: 3 | C7: 45660 | D7: 45
B8: 4 | C8: 45661 | D8: 34
B9: 5 | C9: 45662 | D9: 37
B10: 6 | C10: 45663 | D10: 45
B11: 7 | C11: 45664 | D11: 38
B12: 8 | C12: 45665 | D12: 32
B13: 9 | C13: 45666 | D13: 33
B14: 10 | C14: 45667 | D14: 40
B15: 11 | C15: 45668 | D15: 36
B16: 12 | C16: 45669 | D16: 44
... B43: 39 | C43: 45696 | D43: 45
B44: 40 | C44: 45697 | D44: 40 | H44: Etiquetas de fila | I44: Suma de HISTÓRICO | J44: Suma de PREVISIÓN | M44: AÑO | N44: TRIMESTRE | O44: DEMANDA
B45: 41 | C45: 45698 | D45: 37 | H45: 2025 | M45: 1 | N45: I | O45: =SUM(I46:I48) -> 3821
B46: 42 | C46: 45699 | D46: 52 | H46: Ene | I46: 1221 | N46: II | O46: =SUM(I49:I51) -> 3821
B47: 43 | C47: 45700 | D47: 43 | H47: Feb | I47: 1219 | N47: III | O47: =SUM(I52:I54) -> 3290
B48: 44 | C48: 45701 | D48: 42 | H48: Mar | I48: 1381 | N48: IV | O48: =SUM(I55:I57) -> 3326
B49: 45 | C49: 45702 | D49: 52 | H49: Abr | I49: 1318 | M49: 2 | N49: I | O49: =SUM(I59:I61) -> 3809
B50: 46 | C50: 45703 | D50: 41 | H50: May | I50: 1353 | N50: II | O50: =SUM(I62:I64) -> 3888
B51: 47 | C51: 45704 | D51: 43 | H51: Jun | I51: 1150 | N51: III | O51: =SUM(I65:I67) -> 3111
B52: 48 | C52: 45705 | D52: 45 | H52: Jul | I52: 1173 | K52: =SUM(I46:I51) -> 7642 | N52: IV | O52: =SUM(I68:I70) -> 3222
B53: 49 | C53: 45706 | D53: 30 | H53: Ago | I53: 1150 | M53: 3 | N53: I | O53: =SUM(J72:J74) -> 3736
B54: 50 | C54: 45707 | D54: 40 | H54: Set | I54: 967 | N54: II | O54: =SUM(J75:J77) -> 3820
B55: 51 | C55: 45708 | D55: 35 | H55: Oct | I55: 1084 | N55: III | O55: =SUM(J78:J80) -> 3136
B56: 52 | C56: 45709 | D56: 53 | H56: Nov | I56: 1088 | N56: IV | O56: =SUM(J81:J83) -> 3241
B57: 53 | C57: 45710 | D57: 44 | H57: Dic | I57: 1154 | M57: 4 | N57: I | O57: =SUM(J85:J87) -> 3842
B58: 54 | C58: 45711 | D58: 40 | H58: 2026 | N58: II | O58: =SUM(J88:J90) -> 3884
B59: 55 | C59: 45712 | D59: 48 | H59: Ene | I59: 1248 | K59: =SUM(I46:I51,I59:I64,J72:J77,J85:J90)/4 -> 7655.25 | N59: III | O59: =SUM(J91:J93) -> 3206
B60: 56 | C60: 45713 | D60: 46 | H60: Feb | I60: 1174 | N60: IV | O60: =SUM(J94:J96) -> 3271
B61: 57 | C61: 45714 | D61: 41 | H61: Mar | I61: 1387
B62: 58 | C62: 45715 | D62: 48 | H62: Abr | I62: 1331
B63: 59 | C63: 45716 | D63: 51 | H63: May | I63: 1322
B64: 60 | C64: 45717 | D64: 47 | H64: Jun | I64: 1235
B65: 61 | C65: 45718 | D65: 45 | H65: Jul | I65: 1144
B66: 62 | C66: 45719 | D66: 34 | H66: Ago | I66: 1046
B67: 63 | C67: 45720 | D67: 37 | H67: Set | I67: 921
B68: 64 | C68: 45721 | D68: 34 | H68: Oct | I68: 1028
...

Sheet EOQ_PREVISIÓN
B2: ANÁLISIS DE CANTIDAD ECONÓMICA DE PEDIDO
B4: AÑO | C4: 3 | G4: 4
B5: TRIMESTRE | C5: I | D5: II | E5: III | F5: IV | G5: I | H5: II | I5: III | J5: IV
B6: COSTO UNITARIO | C6: 1000 | D6: 1000 | E6: 1000 | F6: 1000 | G6: 1000 | H6: 1000 | I6: 1000 | J6: 1000
B7: COSTO DE PREPARACIÓN | C7: 1500 | D7: 1500 | E7: 1500 | F7: 1500 | G7: 1500 | H7: 1500 | I7: 1500 | J7: 1500
B8: DEMANDA | C8: =DEMANDA_PREVISIÓN!O53 -> 3736 | D8: =DEMANDA_PREVISIÓN!O54 -> 3820 | E8: =DEMANDA_PREVISIÓN!O55 -> 3136 | F8: =DEMANDA_PREVISIÓN!O56 -> 3241 | G8: =DEMANDA_PREVISIÓN!O57 -> 3842 | H8: =DEMANDA_PREVISIÓN!O58 -> 3884 | I8: =DEMANDA_PREVISIÓN!O59 -> 3206 | J8: =DEMANDA_PREVISIÓN!O60 -> 3271
B9: COSTO DE MANTENIMIENTO | C9: 100 | D9: 100 | E9: 100 | F9: 100 | G9: 100 | H9: 100 | I9: 100 | J9: 100
B11: EOQ | C11: =SQRT((2*C7*C8)/C9) -> 334.78351 | D11: =SQRT((2*D7*D8)/D9) -> 338.52622 | E11: =SQRT((2*E7*E8)/E9) -> 306.72463 | F11: =SQRT((2*F7*F8)/F9) -> 311.81725 | G11: =SQRT((2*G7*G8)/G9) -> 339.49963 | H11: =SQRT((2*H7*H8)/H9) -> 341.35026 | I11: =SQRT((2*I7*I8)/I9) -> 310.12901 | J11: =SQRT((2*J7*J8)/J9) -> 313.25708
B16: AÑO | C16: 3 | G16: 4
B17: TRIMESTRE | C17: I | D17: II | E17: III | F17: IV | G17: I | H17: II | I17: III | J17: IV
B18: DEMANDA (Bidones) | C18: =C8 -> 3736 | D18: =D8 -> 3820 | E18: =E8 -> 3136 | F18: =F8 -> 3241 | G18: =G8 -> 3842 | H18: =H8 -> 3884 | I18: =I8 -> 3206 | J18: =J8 -> 3271
B19: EOQ (Bidones) | C19: =C11 -> 334.78351 | D19: =D11 -> 338.52622 | E19: =E11 -> 306.72463 | F19: =F11 -> 311.81725 | G19: =G11 -> 339.49963 | H19: =H11 -> 341.35026 | I19: =I11 -> 310.12901 | J19: =J11 -> 313.25708
C20: 400 | D20: 400 | E20: 200 | F20: 200 | G20: 400 | H20: 400 | I20: 200 | J20: 200
C24: CANTIDAD | D24: COSTO POR LOTE | E24: COSTO UNITARIO | F24: PENDIENTE
C25: 50 | D25: =$C$7+$C$6*C25 -> 51500 | E25: =D25/C25 -> 1030 | F25: 0
C26: 100 | D26: =$C$7+$C$6*C26 -> 101500 | E26: =D26/C26 -> 1015 | F26: =ABS((E26-E25)/(C26-C25)) -> 0.3
C27: 150 | D27: =$C$7+$C$6*C27 -> 151500 | E27: =D27/C27 -> 1010 | F27: =ABS((E27-E26)/(C27-C26)) -> 0.1
C28: 200 | D28: =$C$7+$C$6*C28 -> 201500 | E28: =D28/C28 -> 1007.5 | F28: =ABS((E28-E27)/(C28-C27)) -> 0.05
C29: 250 | D29: =$C$7+$C$6*C29 -> 251500 | E29: =D29/C29 -> 1006 | F29: =ABS((E29-E28)/(C29-C28)) -> 0.03
C30: 300 | D30: =$C$7+$C$6*C30 -> 301500 | E30: =D30/C30 -> 1005 | F30: =ABS((E30-E29)/(C30-C29)) -> 0.02
C31: 350 | D31: =$C$7+$C$6*C31 -> 351500 | E31: =D31/C31 -> 1004.2857 | F31: =ABS((E31-E30)/(C31-C30)) -> 0.014285714
C32: 400 | D32: =$C$7+$C$6*C32 -> 401500 | E32: =D32/C32 -> 1003.75 | F32: =ABS((E32-E31)/(C32-C31)) -> 0.010714286
C33: 450 | D33: =$C$7+$C$6*C33 -> 451500 | E33: =D33/C33 -> 1003.3333 | F33: =ABS((E33-E32)/(C33-C32)) -> 0.0083333333
C34: 500 | D34: =$C$7+$C$6*C34 -> 501500 | E34: =D34/C34 -> 1003 | F34: =ABS((E34-E33)/(C34-C33)) -> 0.0066666667
C35: 550 | D35: =$C$7+$C$6*C35 -> 551500 | E35: =D35/C35 -> 1002.7273 | F35: =ABS((E35-E34)/(C35-C34)) -> 0.0054545455
C36: 600 | D36: =$C$7+$C$6*C36 -> 601500 | E36: =D36/C36 -> 1002.5 | F36: =ABS((E36-E35)/(C36-C35)) -> 0.0045454545
C37: 650 | D37: =$C$7+$C$6*C37 -> 651500 | E37: =D37/C37 -> 1002.3077 | F37: =ABS((E37-E36)/(C37-C36)) -> 0.0038461538
... C44: 1000 | D44: =$C$7+$C$6*C44 -> 1001500 | E44: =D44/C44 -> 1001.5 | F44: =ABS((E44-E43)/(C44-C43)) -> 0.0015789474

Sheet ROP_PREVISIÓN
C5: AÑO | D5: TRIMESTRE | E5: m | F5: LT | G5: K | H5: s | I5: ROP
C6: 3 | D6: I | E6: =DEMANDA_PREVISIÓN!O45/90 -> 42.455556 | F6: 17 | G6: 3.719 | H6: =_xlfn.STDEV.S(DEMANDA_PREVISIÓN!E735:E824) -> 6.1612133 | I6: =E6*F6+G6*H6*SQRT(F6) -> 816.21944
D7: II | E7: =DEMANDA_PREVISIÓN!O46/90 -> 42.455556 | F7: 15 | G7: 3.719 | H7: =_xlfn.STDEV.S(DEMANDA_PREVISIÓN!E826:E915) -> 5.8405359 | I7: =E7*F7+G7*H7*SQRT(F7) -> 720.95822
D8: III | E8: =DEMANDA_PREVISIÓN!O47/90 -> 36.555556 | F8: 11 | G8: 3.719 | H8: =_xlfn.STDEV.S(DEMANDA_PREVISIÓN!E916:E1005) -> 5.810963 | I8: =E8*F8+G8*H8*SQRT(F8) -> 473.78659
D9: IV | E9: =DEMANDA_PREVISIÓN!O48/90 -> 36.955556 | F9: 11 | G9: 3.719 | H9: =_xlfn.STDEV.S(DEMANDA_PREVISIÓN!E1006:E1095) -> 4.9438293 | I9: =E9*F9+G9*H9*SQRT(F9) -> 467.49091
C10: 4 | D10: I | E10: =DEMANDA_PREVISIÓN!O49/90 -> 42.322222 | F10: 15 | G10: 3.719 | H10: =_xlfn.STDEV.S(DEMANDA_PREVISIÓN!E1096:E1185) -> 6.391171 | I10: =E10*F10+G10*H10*SQRT(F10) -> 726.88936
D11: II | E11: =DEMANDA_PREVISIÓN!O50/90 -> 43.2 | F11: 15 | G11: 3.719 | H11: =_xlfn.STDEV.S(DEMANDA_PREVISIÓN!E1186:E1275) -> 5.8798732 | I11: =E11*F11+G11*H11*SQRT(F11) -> 732.69149
D12: III | E12: =DEMANDA_PREVISIÓN!O51/90 -> 34.566667 | F12: 11 | G12: 3.719 | H12: =_xlfn.STDEV.S(DEMANDA_PREVISIÓN!E1276:E1365) -> 5.852206 | I12: =E12*F12+G12*H12*SQRT(F12) -> 452.41753
D13: IV | E13: =DEMANDA_PREVISIÓN!O52/90 -> 35.8 | F13: 11 | G13: 3.719 | H13: =_xlfn.STDEV.S(DEMANDA_PREVISIÓN!E1366:E1455) -> 5.0770468 | I13: =E13*F13+G13*H13*SQRT(F13) -> 456.42297
C17: AÑO | D17: AÑO 3 | H17: AÑO 4
C18: TRIMESTRE | D18: I | E18: II | F18: III | G18: IV | H18: I | I18: II | J18: III | K18: IV
C19: EOQ (Bidones) | D19: 400 | E19: 400 | F19: 200 | G19: 200 | H19: 400 | I19: 400 | J19: 200 | K19: 200
C20: ROP (Bidones) | D20: =E6*F6+G6*H6 -> 744.658 | E20: =E7*F7+G7*H7 -> 658.55429 | F20: =E8*F8+G8*H8 -> 423.72208 | G20: =E9*F9+G9*H9 -> 424.89721 | H20: =E10*F10+G10*H10 -> 658.6021 | I20: =E11*F11+G11*H11 -> 669.86725 | J20: =E12*F12+G12*H12 -> 401.99769 | K20: =E13*F13+G13*H13 -> 412.68154
C21: ROP Redondeo | D21: 700 | E21: 700 | F21: 450 | G21: 450 | H21: 700 | I21: 700 | J21: 450 | K21: 450
E735: =ROP_PREVISIÓN!R12 -> 0

Sheet TRANSPORTE_PREVISIÓN
B2: ANÁLISIS DE TRANSPORTE
B4: TRANSPORTE | C4: COSTO | D4: BIDONES | E4: COSTO UNITARIO | F4: TIEMPO DE ENVÍO (Días)
B5: Camión | C5: $15.000,00 | D5: 200 | E5: 75 | F5: 7
D6: 150 | E6: 100
D7: 100 | E7: 150
D8: 50 | E8: 300
B9: Correo | C9: $150,00 | D9: 1 | E9: 150 | F9: 1
D17: =15000/200 -> 75

Sheet CAPACIDAD_PREVISIÓN
B2: ANÁLISIS DE CAPACIDAD | J2: 400
B4: DEMANDA ANUAL (Bidones) | C4: CAPACIDAD (Bidones/Día) | D4: PRODUCCIÓN ANUAL (Bidones) | E4: DEMANDA EN LOS TRIMESTRES I - II (SEMESTRE) (Bidones) | F4: PRODUCCIÓN CADA 2 TRIMESTRES (Bidones) | G4: COSTO POR AUMENTAR CAPACIDAD | H4: SALDO FINAL
B5: =AVERAGE(DEMANDA_PREVISIÓN!M46:AB46) -> 3821 | C5: 20 | D5: =C5*365 -> 7300 | E5: =(SUM(DEMANDA_PREVISIÓN!O45:O46)+SUM(DEMANDA_PREVISIÓN!O49:O50)+SUM(DEMANDA_PREVISIÓN!O53:O54)+SUM(DEMANDA_PREVISIÓN!O57:O58))/4 -> 7655.25 | F5: =C5*180 -> 3600 | G5: - | H5: =3142*1000 -> 3142000
C6: 25 | D6: =C6*365 -> 9125 | F6: =C6*180 -> 4500 | G6: =(C6-$C$5)*50000 -> 250000 | H6: =$H$5-G6 -> 2892000 | J6: e | K6: 120 | L6: =20*31 -> 620 | M6: =K6-L6 -> -500 | N6: =21*20 -> 420 | P6: Revisae inventario | R6: 10000 LOTE | S6: 50 CAPACIDAD
C7: 30 | D7: =C7*365 -> 10950 | F7: =C7*180 -> 5400 | G7: =(C7-$C$5)*50000 -> 500000 | H7: =$H$5-G7 -> 2642000 | J7: f | K7: 247 | L7: =20*31 -> 620 | M7: 20 | P7: 9DIAS
C8: 35 | D8: =C8*365 -> 12775 | F8: =C8*180 -> 6300 | G8: =(C8-$C$5)*50000 -> 750000 | H8: =$H$5-G8 -> 2392000 | J8: m | K8: 473 | L8: =20*31 -> 620 | M8: 30
C9: 40 | D9: =C9*365 -> 14600 | F9: =C9*180 -> 7200 | G9: =(C9-$C$5)*50000 -> 1000000 | H9: =$H$5-G9 -> 2142000 | L9: =50*30 -> 1500
C10: 45 | D10: =C10*365 -> 16425 | F10: =C10*180 -> 8100 | G10: =(C10-$C$5)*50000 -> 1250000 | H10: =$H$5-G10 -> 1892000 | J10: =F10-E5 -> 444.75 | L10: =50*30 -> 1500
C11: 50 | D11: =C11*365 -> 18250 | F11: =C11*180 -> 9000 | G11: =(C11-$C$5)*50000 -> 1500000 | H11: =$H$5-G11 -> 1642000 | J11: =F11-E6 -> 9000 | L11: =50*30 -> 1500
C12: 55 | D12: =C12*365 -> 20075 | F12: =C12*180 -> 9900 | G12: =(C12-$C$5)*50000 -> 1750000 | H12: =$H$5-G12 -> 1392000 | J12: =F12-E7 -> 9900 | L12: =50*30 -> 1500
C13: 60 | D13: =C13*365 -> 21900 | F13: =C13*180 -> 10800 | G13: =(C13-$C$5)*50000 -> 2000000 | H13: =$H$5-G13 -> 1142000 | J13: =F13-E8 -> 10800 | L13: =50*30 -> 1500
L14: =50*30 -> 1500
L15: =50*30 -> 1500
L16: =50*30 -> 1500
L17: =50*30 -> 1500
K18: =H11 -> 1642000

Sheet PROYECCIÓN_PREVISIÓN_EDITAR (O)
B4: AÑO | C4: TRIMESTRE | D4: MES | E4: DIA | F4: DEMANDA | H4: ALMACEN | I4: CAMION | J4: EN PROCESO | L4: CAPACIDAD | M4: ROP | Q4: HORA | R4: DÍA
B5: - | C5: - | D5: - | E5: 730 | F5: =PRUEBA_HISTÓRICO!F734 -> 24 | H5: 0 | I5: 150 | J5: 150 | L5: 20 | M5: 800 | Q5: 10.916667 | R5: 1
B6: 2027 | C6: I | D6: Enero | E6: 731 | F6: =DEMANDA_PREVISIÓN!E735 -> 44 | H6: 0 | I6: 150 | J6: 150 | L6: 20 | M6: 800 | Q6: 10.926273
E7: 732 | F7: =DEMANDA_PREVISIÓN!E736 -> 41 | H7: 0 | I7: 150 | J7: 150 | L7: 20 | M7: 800 | Q7: 10.93588
E8: 733 | F8: =DEMANDA_PREVISIÓN!E737 -> 41 | H8: 0 | I8: 150 | J8: 150 | L8: 20 | M8: 800 | Q8: 10.945486
E9: 734 | F9: =DEMANDA_PREVISIÓN!E738 -> 54 | H9: 150 | J9: 150 | L9: 20 | M9: 800 | Q9: 10.955093
E10: 735 | F10: =DEMANDA_PREVISIÓN!E739 -> 40 | H10: =H9-F10 -> 110 | I10: 150 | J10: 150 | L10: 20 | M10: 800 | Q10: 10.964699
E11: 736 | F11: =DEMANDA_PREVISIÓN!E740 -> 46 | H11: =H10-F11 -> 64 | I11: 150 | J11: 200 | L11: 20 | M11: 800 | N11: =J11/L11 -> 10 | O11: =1500+200*1000 -> 201500 | Q11: 10.974306
E12: 737 | F12: =DEMANDA_PREVISIÓN!E741 -> 33 | H12: =H11-F12 -> 31 | I12: 150 | J12: 200 | L12: 20 | M12: 800 | N12: =J12/L12 -> 10 | Q12: 10.983912
E13: 738 | F13: =DEMANDA_PREVISIÓN!E742 -> 46 | H13: 0 | I13: 150 | J13: 200 | L13: 20 | M13: 800 | N13: =J13/L13 -> 10 | Q13: 10.993519
E14: 739 | F14: =DEMANDA_PREVISIÓN!E743 -> 37 | H14: 0 | I14: 150 | J14: 200 | L14: 20 | M14: 800 | N14: =J14/L14 -> 10 | P14: costo de produccion | Q14: 11.003125 | R14: 2
E15: 740 | F15: =DEMANDA_PREVISIÓN!E744 -> 35 | H15: 0 | I15: 150 | J15: 200 | L15: 20 | M15: 800 | N15: =J15/L15 -> 10 | Q15: 11.012731
E16: 741 | F16: =DEMANDA_PREVISIÓN!E745 -> 37 | H16: 0 | I16: 150 | J16: 200 | L16: 20 | M16: 800 | N16: =J16/L16 -> 10 | O16: =5000/200 -> 25 | P16: =O16*O11 -> 5037500 | Q16: 11.022338
E17: 742 | F17: =DEMANDA_PREVISIÓN!E746 -> 31 | H17: 150 | J17: 200 | L17: 20 | M17: 800 | N17: =J17/L17 -> 10 | O17: en 1 año(promedio) | Q17: 11.031944
E18: 743 | F18: =DEMANDA_PREVISIÓN!E747 -> 46 | H18: =H17-F18 -> 104 | J18: 200 | L18: 20 | M18: 800 | N18: =J18/L18 -> 10 | Q18: 11.041551
E19: 744 | F19: =DEMANDA_PREVISIÓN!E748 -> 47 | H19: =H18-F19 -> 57 | J19: 200 | L19: 20 | M19: 800 | N19: =J19/L19 -> 10 | Q19: 11.051157
E20: 745 | F20: =DEMANDA_PREVISIÓN!E749 -> 34 | H20: =H19-F20 -> 23 | I20: 200 | J20: 200 | L20: 20 | M20: 800 | N20: =J20/L20 -> 10 | Q20: 11.060764
E21: 746 | F21: =DEMANDA_PREVISIÓN!E750 -> 41 | H21: 0 | I21: 200 | J21: 200 | L21: 20 | M21: 800 | Q21: 11.07037
E22: 747 | F22: =DEMANDA_PREVISIÓN!E751 -> 40 | H22: 0 | I22: 200 | J22: 200 | L22: 20 | M22: 800 | Q22: 11.079977
E23: 748 | F23: =DEMANDA_PREVISIÓN!E752 -> 28 | H23: 0 | I23: 200 | J23: 200 | L23: 20 | M23: 800 | Q23: 11.089583
E24: 749 | F24: =DEMANDA_PREVISIÓN!E753 -> 42 | H24: 0 | I24: 200 | J24: 200 | L24: 20 | M24: 800 | Q24: 11.09919
E25: 750 | F25: =DEMANDA_PREVISIÓN!E754 -> 32 | H25: 0 | I25: 200 | J25: 200 | L25: 20 | M25: 800 | Q25: 11.108796
E26: 751 | F26: =DEMANDA_PREVISIÓN!E755 -> 48 | H26: 0 | I26: 200 | J26: 200 | L26: 20 | M26: 800 | Q26: 11.118403
E27: 752 | F27: =DEMANDA_PREVISIÓN!E756 -> 31 | H27: 200 | J27: 200 | L27: 20 | M27: 800 | Q27: 11.128009
E28: 753 | F28: =DEMANDA_PREVISIÓN!E757 -> 48 | H28: =H27-F28 -> 152 | J28: 200 | L28: 20 | M28: 800 | Q28: 11.137616
E29: 754 | F29: =DEMANDA_PREVISIÓN!E758 -> 50 | H29: =H28-F29 -> 102 | J29: 200 | L29: 20 | M29: 800 | Q29: 11.147222
E30: 755 | F30: =DEMANDA_PREVISIÓN!E759 -> 38 | H30: =H29-F30 -> 64 | I30: 200 | J30: 200 | L30: 20 | M30: 800 | Q30: 11.156829
E31: 756 | F31: =DEMANDA_PREVISIÓN!E760 -> 31 | H31: =H30-F31 -> 33 | I31: 200 | J31: 200 | L31: 20 | M31: 800 | Q31: 11.166435
E32: 757 | F32: =DEMANDA_PREVISIÓN!E761 -> 41 | H32: 0 | I32: 200 | J32: 200 | L32: 20 | M32: 800 | Q32: 11.176042
E33: 758 | F33: =DEMANDA_PREVISIÓN!E762 -> 44 | H33: 0 | I33: 200 | J33: 200 | L33: 20 | M33: 800 | Q33: 11.185648
E34: 759 | F34: =DEMANDA_PREVISIÓN!E763 -> 34 | H34: 0 | I34: 200 | J34: 200 | L34: 20 | M34: 800 | Q34: 11.195255
E35: 760 | F35: =DEMANDA_PREVISIÓN!E764 -> 34 | H35: 0 | I35: 200 | J35: 200 | L35: 20 | M35: 800 | Q35: 11.204861
E36: 761 | F36: =DEMANDA_PREVISIÓN!E765 -> 49 | H36: 0 | I36: 200 | J36: 200 | L36: 20 | M36: 800 | Q36: 11.214468
D37: Febrero | E37: 762 | F37: =DEMANDA_PREVISIÓN!E766 -> 41 | H37: 200 | J37: 200 | L37: 20 | M37: 800 | Q37: 11.224074
E38: 763 | F38: =DEMANDA_PREVISIÓN!E767 -> 40 | H38: =H37-F38 -> 160 | J38: 200 | L38: 20 | M38: 800 | Q38: 11.233681
E39: 764 | F39: =DEMANDA_PREVISIÓN!E768 -> 46 | H39: =H38-F39 -> 114 | J39: 200 | L39: 20 | M39: 800 | Q39: 11.243287
E40: 765 | F40: =DEMANDA_PREVISIÓN!E769 -> 31 | H40: =H39-F40 -> 83 | I40: 200 | J40: 200 | L40: 20 | M40: 800 | Q40: 11.252894
E41: 766 | F41: =DEMANDA_PREVISIÓN!E770 -> 38 | H41: =H40-F41 -> 45 | I41: 200 | J41: 200 | L41: 20 | M41: 800 | Q41: 11.2625
E42: 767 | F42: =DEMANDA_PREVISIÓN!E771 -> 39 | H42: =H41-F42 -> 6 | I42: 200 | J42: 200 | L42: 20 | M42: 800 | Q42: 11.272106
E43: 768 | F43: =DEMANDA_PREVISIÓN!E772 -> 40 | H43: 0 | I43: 200 | J43: 200 | L43: 20 | M43: 800 | Q43: 11.281713
...

Sheet PROYECCIÓN_CONTINUA_BORRADOR
N1: PRODUCCIÓN CONTINUA
T2: TEMPORADA BAJA - LOTES GRANDES
N3: PRODUCCIÓN POR LOTES
B4: TRIMESTRE | C4: MES | D4: DIA | E4: DEMANDA | G4: ALMACEN | H4: CAMION | I4: EN PROCESO | K4: CAPACIDAD | L4: ROP | R4: ROP
B5: I | C5: 1 | D5: 730 | E5: =DEMANDA_PREVISIÓN!D734 -> 24 | G5: 0 | H5: 150 | I5: 150 | K5: 20 | N5: ROP | O5: 150 | Q5: CAMBIAR | R5: =H5+K5 -> 170
D6: 731 | E6: =DEMANDA_PREVISIÓN!E735 -> 44 | G6: 0 | H6: 150 | I6: 150 | K6: 20 | W6: **EDITAR
D7: 732 | E7: =DEMANDA_PREVISIÓN!E736 -> 41 | G7: 0 | H7: 150 | I7: 150 | K7: 20
D8: 733 | E8: =DEMANDA_PREVISIÓN!E737 -> 41 | G8: 0 | H8: 150 | I8: 150 | K8: 20 | N8: 150 | O8: lote
D9: 734 | E9: =DEMANDA_PREVISIÓN!E738 -> 54 | G9: 150 | I9: 150 | K9: 20 | T9: Si quiero que este en constante proceso, el ROE debe ser alto
D10: 735 | E10: =DEMANDA_PREVISIÓN!E739 -> 40 | G10: =G9-E10 -> 110 | H10: 150 | I10: 150 | K10: 20 | N10: 20 | O10: capacidad | S10: T1 | T10: Punto de reorden ALTO
C11: 2 | D11: 736 | E11: =DEMANDA_PREVISIÓN!E740 -> 46 | G11: =G10-E11 -> 64 | H11: 150 | I11: 200 | K11: 20 | S11: T2 | T11: Punto de reorden ALTO
D12: 737 | E12: =DEMANDA_PREVISIÓN!E741 -> 33 | G12: =G11-E12 -> 31 | H12: 150 | I12: 200 | K12: 20 | S12: T3 | T12: Punto de reorden ALTO
D13: 738 | E13: =DEMANDA_PREVISIÓN!E742 -> 46 | G13: 0 | H13: 150 | I13: 200 | K13: 20 | N13: =N8/N10 -> 7.5 | O13: días | S13: T4 | T13: Punto de reorden ALTO
D14: 739 | E14: =DEMANDA_PREVISIÓN!E743 -> 37 | G14: 0 | H14: 150 | I14: 200 | K14: 20 | N14: 7 | S14: T5 | T14: Punto de reorden BAJO
D15: 740 | E15: =DEMANDA_PREVISIÓN!E744 -> 35 | G15: 0 | H15: 150 | I15: 200 | K15: 20 | N15: =14.5 -> 14.5 | O15: días | S15: T6 | T15: Punto de reorden BAJO
D16: 741 | E16: =DEMANDA_PREVISIÓN!E745 -> 37 | G16: 0 | H16: 150 | I16: 200 | K16: 20 | S16: T7 | T16: Punto de reorden MEDIO
D17: 742 | E17: =DEMANDA_PREVISIÓN!E746 -> 31 | G17: 150 | I17: 200 | K17: 20 | S17: T8 | T17: Punto de reorden BAJO
D18: 743 | E18: =DEMANDA_PREVISIÓN!E747 -> 46 | G18: =G17-E18 -> 104 | I18: 200 | K18: 20
D19: 744 | E19: =DEMANDA_PREVISIÓN!E748 -> 47 | G19: =G18-E19 -> 57 | I19: 200 | K19: 20 | N19: 400 | S19: Alto producción continua
D20: 745 | E20: =DEMANDA_PREVISIÓN!E749 -> 34 | G20: =G19-E20 -> 23 | H20: 200 | I20: 200 | K20: 20 | S20: Bajo para tener días de producción
D21: 746 | E21: =DEMANDA_PREVISIÓN!E750 -> 41 | G21: 0 | H21: 200 | I21: 200 | K21: 200 | N21: 80
D22: 747 | E22: =DEMANDA_PREVISIÓN!E751 -> 40 | G22: 0 | H22: 200 | I22: 200 | K22: 200 | S22: CAMBIAR LA CANTIDAD DE PRODUCCIÓN - TEMPORADA BAJA
D23: 748 | E23: =DEMANDA_PREVISIÓN!E752 -> 28 | G23: 0 | H23: 200 | I23: 200 | K23: 200 | N23: =N19/N21 -> 5 | O23: días | U23: Tener almenos algo de inventario (Se logra teniendo un punto de reorden alto)
D24: 749 | E24: =DEMANDA_PREVISIÓN!E753 -> 42 | G24: 0 | H24: 200 | I24: 200 | K24: 200
D25: 750 | E25: =DEMANDA_PREVISIÓN!E754 -> 32 | G25: 0 | H25: 200 | I25: 200 | K25: 200 | O25: 14 minutos
D26: 751 | E26: =DEMANDA_PREVISIÓN!E755 -> 48 | G26: 0 | H26: 200 | I26: 200 | K26: 200
D27: 752 | E27: =DEMANDA_PREVISIÓN!E756 -> 31 | G27: 200 | I27: 200 | K27: 200 | N27: ROP | O27: 200
D28: 753 | E28: =DEMANDA_PREVISIÓN!E757 -> 48 | G28: =G27-E28 -> 152 | I28: 200 | K28: 200
D29: 754 | E29: =DEMANDA_PREVISIÓN!E758 -> 50 | G29: =G28-E29 -> 102 | I29: 200 | K29: 200
D30: 755 | E30: =DEMANDA_PREVISIÓN!E759 -> 38 | G30: =G29-E30 -> 64 | H30: 200 | I30: 200 | K30: 200 | O30: CAMION O CORREO
D31: 756 | E31: =DEMANDA_PREVISIÓN!E760 -> 31 | G31: =G30-E31 -> 33 | H31: 200 | I31: 200 | K31: 20
D32: 757 | E32: =DEMANDA_PREVISIÓN!E761 -> 41 | G32: 0 | H32: 200 | I32: 200 | K32: 20 | N32: FABRICA | O32: CAMIÓN | P32: INVENTARIO | R32: CLIENTE
D33: 758 | E33: =DEMANDA_PREVISIÓN!E762 -> 44 | G33: 0 | H33: 200 | I33: 200 | K33: 20 | Q33: 150
D34: 759 | E34: =DEMANDA_PREVISIÓN!E763 -> 34 | G34: 0 | H34: 200 | I34: 200 | K34: 20
D35: 760 | E35: =DEMANDA_PREVISIÓN!E764 -> 34 | G35: 0 | H35: 200 | I35: 200 | K35: 20
D36: 761 | E36: =DEMANDA_PREVISIÓN!E765 -> 49 | G36: 0 | H36: 200 | I36: 200 | K36: 20
D37: 762 | E37: =DEMANDA_PREVISIÓN!E766 -> 41 | G37: 200 | I37: 200 | K37: 20
D38: 763 | E38: =DEMANDA_PREVISIÓN!E767 -> 40 | G38: =G37-E38 -> 160 | I38: 200 | K38: 20
D39: 764 | E39: =DEMANDA_PREVISIÓN!E768 -> 46 | G39: =G38-E39 -> 114 | I39: 200 | K39: 20
D40: 765 | E40: =DEMANDA_PREVISIÓN!E769 -> 31 | G40: =G39-E40 -> 83 | H40: 200 | I40: 200 | K40: 20
...

Sheet BITÁCORA
B3: N° | C3: DÍA (REAL) | D3: ENCARGADO | E3: TRIMESTRE (SIMULACIÓN) | F3: DÍA (SIMULACIÓN) | G3: PARÁMETRO | H3: NUEVO VALOR
B4: 1 | C4: 45923 | E4: T1
B5: 2
B6: 3
B7: 4 | C7: 45924 | E7: T2
B8: 5
B9: 6
B10: 7
B11: 8 | C11: 45925 | E11: T4
B12: 9
B13: 10
B14: 11 | C14: 45926 | E14: T5
B15: 12
B16: 13
B17: 14
B18: 15 | C18: 45927 | E18: T6
B19: 17
B20: 18 | C20: 45928 | E20: T7
B21: 19
B22: 20
B23: 21
B24: 22
B25: 25 | C25: 45929 | E25: T8
B26: 26
B27: 27
B28: 28
B29: 29
B30: 30
B31: 31
B32: 32 | C32: 45930
B33: 33
B34: 34
B35: 35
B36: 36
